Workbook

Sheet Cover Page
A1: COVER PAGE - USD ($) | B1: 12 Months Ended
B2: Dec. 30, 2023 | C2: Feb. 15, 2024 | D2: Jun. 30, 2023
A3: Cover [Abstract]
A4: Document Type | B4: 10-K
A5: Document Annual Report | B5: true
A6: Document Period End Date | B6: Dec. 30, 2023
A7: Current Fiscal Year End Date | B7: --12-30
A8: Document Transition Report | B8: false
A9: Entity File Number | B9: 001-38713
A10: Entity Registrant Name | B10: YETI Holdings, Inc.
A11: Entity Incorporation, State or Country Code | B11: DE
A12: Entity Tax Identification Number | B12: 45-5297111
A13: Entity Address, Address Line One | B13: 7601 Southwest Parkway
A14: Entity Address, City or Town | B14: Austin
A15: Entity Address, State or Province | B15: TX
... A31: Entity Shell Company | B31: false
A32: Entity Public Float | D32: 2644447229
A33: Entity Common Stock, Shares Outstanding | C33: 86933474
A34: Documents Incorporated by Reference | B34: Portions of the Proxy Statement for the registrant’s 2023 Annual Meeting of Stockholders, to be filed with the Securities and Exchange Commission no later than 120 days after December 30, 2023, are incorporated by reference in Part III herein.
A35: Entity Central Index Key | B35: 0001670592
A36: Amendment Flag | B36: false
A37: Document Fiscal Year Focus | B37: 2023
A38: Document Fiscal Period Focus | B38: FY

Sheet RATIOS
B1: FINANCIAL RATIOS
E2: 2023 | F2: 2022 | G2: 2021 | H2: 2020 | I2: 2019
B3: LIQUIDITY RATIOS
B4: Current Ratio | E4: ='BALANCE SHEET'!B7/'BALANCE SHEET'!B21 -> 2.2954641 | F4: ='BALANCE SHEET'!C7/'BALANCE SHEET'!C21 -> 1.7575787 | G4: ='BALANCE SHEET'!D7/'BALANCE SHEET'!D21 -> 1.9077092 | H4: ='BALANCE SHEET'!E7/'BALANCE SHEET'!E21 -> 1.6558891 | I4: ='BALANCE SHEET'!F7/'BALANCE SHEET'!F21 -> 2.1169794 | K4: Should be between 100-300
B5: Quick Ratio | E5: =('BALANCE SHEET'!B7-'BALANCE SHEET'!B21)/'BALANCE SHEET'!B5 -> 1.530367 | F5: =('BALANCE SHEET'!C7-'BALANCE SHEET'!C21)/'BALANCE SHEET'!C5 -> 0.83432953 | G5: =('BALANCE SHEET'!D7-'BALANCE SHEET'!D21)/'BALANCE SHEET'!D5 -> 1.1492486 | H5: =('BALANCE SHEET'!E7-'BALANCE SHEET'!E21)/'BALANCE SHEET'!E5 -> 1.3470605 | I5: =('BALANCE SHEET'!F7-'BALANCE SHEET'!F21)/'BALANCE SHEET'!F5 -> 1.0244211 | K5: To pay current liability, the company must sell inventory to repay. Quick cash must be between 50 -150
B7: ASSET MANAGEMENT RATIOS
B8: Inventory Turnover Ratio | E8: ='BALANCE SHEET'!B5/'INCOME STATEMENT'!B5 -> 0.47127222 | F8: ='BALANCE SHEET'!C5/'INCOME STATEMENT'!C5 -> 0.44650472 | G8: ='BALANCE SHEET'!D5/'INCOME STATEMENT'!D5 -> 0.53601759 | H8: ='BALANCE SHEET'!E5/'INCOME STATEMENT'!E5 -> 0.30266916 | I8: ='BALANCE SHEET'!F5/'INCOME STATEMENT'!F5 -> 0.42356644 | K8: How fast does inventory turn over
B9: DSO (Days Sales Outstanding) | E9: ='BALANCE SHEET'!B4/'INCOME STATEMENT'!B4 -> 0.057739947 | F9: ='BALANCE SHEET'!C4/'INCOME STATEMENT'!C4 -> 0.049802473 | G9: ='BALANCE SHEET'!D4/'INCOME STATEMENT'!D4 -> 0.077626402 | H9: ='BALANCE SHEET'!E4/'INCOME STATEMENT'!E4 -> 0.059920987 | I9: ='BALANCE SHEET'!F4/'INCOME STATEMENT'!F4 -> 0.090494608 | K9: measure of how long it takes for a company to collect payment after making a sale. It indicates the efficiency of the company’s receivables collection process.
B10: Fixed assets Turnover Ratio | E10: ='INCOME STATEMENT'!B4/'BALANCE SHEET'!B7 -> 1.8139807 | F10: ='INCOME STATEMENT'!C4/'BALANCE SHEET'!C7 -> 2.2189145 | G10: ='INCOME STATEMENT'!D4/'BALANCE SHEET'!D7 -> 1.8320559 | H10: ='INCOME STATEMENT'!E4/'BALANCE SHEET'!E7 -> 2.2911393 | I10: ='INCOME STATEMENT'!F4/'BALANCE SHEET'!F7 -> 2.5342993 | K10: measures how efficiently a company is using its fixed assets (such as property, plant, and equipment) to generate sales.
B12: Debt Management Ratio
B13: Total debt to total capital | E13: ='BALANCE SHEET'!B21/'BALANCE SHEET'!B25 -> 0.69450052 | F13: ='BALANCE SHEET'!C21/'BALANCE SHEET'!C25 -> 0.74331986 | G13: ='BALANCE SHEET'!D21/'BALANCE SHEET'!D25 -> 0.69781226 | H13: ='BALANCE SHEET'!E21/'BALANCE SHEET'!E25 -> 0.64139004 | I13: ='BALANCE SHEET'!F21/'BALANCE SHEET'!F25 -> 0.33556767 | K13: A higher ratio suggests the company is more leveraged (i.e., using more debt to finance operations
B14: Times Interest Earned Ratio | E14: ='INCOME STATEMENT'!B8/'INCOME STATEMENT'!B9 -> -239.3397 | F14: ='INCOME STATEMENT'!C8/'INCOME STATEMENT'!C9 -> -28.293999 | G14: ='INCOME STATEMENT'!D8/'INCOME STATEMENT'!D9 -> -82.34142 | H14: ='INCOME STATEMENT'!E8/'INCOME STATEMENT'!E9 -> -23.400655 | I14: ='INCOME STATEMENT'!F8/'INCOME STATEMENT'!F9 -> -4.1219064 | K14: A higher ratio indicates a greater ability to pay interest on its debt.
B16: Profitability Ratios
B17: Operating Margin | E17: ='INCOME STATEMENT'!B8/'INCOME STATEMENT'!B4 -> 0.13592345 | F17: ='INCOME STATEMENT'!C8/'INCOME STATEMENT'!C4 -> 0.079212172 | G17: ='INCOME STATEMENT'!D8/'INCOME STATEMENT'!D4 -> 0.19485481 | H17: ='INCOME STATEMENT'!E8/'INCOME STATEMENT'!E4 -> 0.1962342 | I17: ='INCOME STATEMENT'!F8/'INCOME STATEMENT'!F4 -> 0.098246317 | K17: This is the percentage of revenue that remains after subtracting operating expenses
B18: Profit Margin | E18: ='INCOME STATEMENT'!B13/'INCOME STATEMENT'!B4 -> 0.10241977 | F18: ='INCOME STATEMENT'!C13/'INCOME STATEMENT'!C4 -> 0.05622603 | G18: ='INCOME STATEMENT'!D13/'INCOME STATEMENT'!D4 -> 0.15067587 | H18: ='INCOME STATEMENT'!E13/'INCOME STATEMENT'!E4 -> 0.14271137 | I18: ='INCOME STATEMENT'!F13/'INCOME STATEMENT'!F4 -> 0.055195495 | K18: profit margin is the percentage of sales that has turned into profit
B19: Return on total assets | E19: ='INCOME STATEMENT'!B13/'BALANCE SHEET'!B13 -> 0.13096365 | F19: ='INCOME STATEMENT'!C13/'BALANCE SHEET'!C13 -> 0.083298584 | G19: ='INCOME STATEMENT'!D13/'BALANCE SHEET'!D13 -> 0.19391552 | H19: ='INCOME STATEMENT'!E13/'BALANCE SHEET'!E13 -> 0.2113797 | I19: ='INCOME STATEMENT'!F13/'BALANCE SHEET'!F13 -> 0.08011259 | K19: measures the company’s ability to generate profit from its assets.
B20: Return on Common Equity | E20: ='INCOME STATEMENT'!B13/'BALANCE SHEET'!B34 -> 0.20626248 | F20: ='INCOME STATEMENT'!C13/'BALANCE SHEET'!C34 -> 0.14316475 | G20: ='INCOME STATEMENT'!D13/'BALANCE SHEET'!D34 -> 0.30462623 | H20: ='INCOME STATEMENT'!E13/'BALANCE SHEET'!E34 -> 0.61060598 | I20: ='INCOME STATEMENT'!F13/'BALANCE SHEET'!F34 -> -0.75649487 | K20: A high return on equity indicates the company is effectively using shareholders' investments to generate profits.
B21: Return on invested Capital | E21: =('INCOME STATEMENT'!B8*(1--0.2313)/('BALANCE SHEET'!B25+'BALANCE SHEET'!B35)) -> 0.21400566 | F21: =('INCOME STATEMENT'!C8*(1--0.2313)/('BALANCE SHEET'!C25+'BALANCE SHEET'!C35)) -> 0.14449606 | G21: =('INCOME STATEMENT'!D8*(1--0.2313)/('BALANCE SHEET'!D25+'BALANCE SHEET'!D35)) -> 0.20211962 | H21: =('INCOME STATEMENT'!E8*(1--0.2313)/('BALANCE SHEET'!E25+'BALANCE SHEET'!E35)) -> 0.22246903 | I21: =('INCOME STATEMENT'!F8*(1--0.2313)/('BALANCE SHEET'!F25+'BALANCE SHEET'!F35)) -> 0.097210146 | K21: an indicator of how well the company is using its capital to generate profits.
B22: Basic earning Power | E22: ='INCOME STATEMENT'!B8/'BALANCE SHEET'!B13 -> 0.17380465 | F22: ='INCOME STATEMENT'!C8/'BALANCE SHEET'!C13 -> 0.11735244 | G22: ='INCOME STATEMENT'!D8/'BALANCE SHEET'!D13 -> 0.25077255 | H22: ='INCOME STATEMENT'!E8/'BALANCE SHEET'!E13 -> 0.29065607 | I22: ='INCOME STATEMENT'!F8/'BALANCE SHEET'!F13 -> 0.142598 | K22: evaluates a company’s ability to generate earnings from its assets before the effects of taxes and interest expenses.
B24: DuPont Equation
B25: (ROE) Return on Equity | E25: ='INCOME STATEMENT'!B13/'INCOME STATEMENT'!B4*'INCOME STATEMENT'!B4/'BALANCE SHEET'!B13*'BALANCE SHEET'!B13/('BALANCE SHEET'!B34+'BALANCE SHEET'!B35) -> 0.10979838 | F25: ='INCOME STATEMENT'!C13/'INCOME STATEMENT'!C4*'INCOME STATEMENT'!C4/'BALANCE SHEET'!C13*'BALANCE SHEET'!C13/('BALANCE SHEET'!C34+'BALANCE SHEET'!C35) -> 0.077792397 | G25: ='INCOME STATEMENT'!D13/'INCOME STATEMENT'!D4*'INCOME STATEMENT'!D4/'BALANCE SHEET'!D13*'BALANCE SHEET'!D13/('BALANCE SHEET'!D34+'BALANCE SHEET'!D35) -> 0.11848908 | H25: ='INCOME STATEMENT'!E13/'INCOME STATEMENT'!E4*'INCOME STATEMENT'!E4/'BALANCE SHEET'!E13*'BALANCE SHEET'!E13/('BALANCE SHEET'!E34+'BALANCE SHEET'!E35) -> 0.15702184 | I25: ='INCOME STATEMENT'!F13/'INCOME STATEMENT'!F4*'INCOME STATEMENT'!F4/'BALANCE SHEET'!F13*'BALANCE SHEET'!F13/('BALANCE SHEET'!F34+'BALANCE SHEET'!F35) -> 0.089601347 | K25: This is a measure of the profitability of a company relative to shareholders' equity.

Sheet GRAPH

Sheet BALANCE SHEET
A1: CONSOLIDATED BALANCE SHEETS - USD ($) $ in Thousands | B1: Dec. 30, 2023 | C1: Dec. 31, 2022 | D1: Jan. 01, 2021 | E1: Dec.28, 2020 | F1: Dec. 28, 2019
A2: Current assets
A3: Cash | B3: 438960 | C3: 234741 | D3: 312189 | E3: 253283 | F3: 72515
A4: Accounts receivable, net | B4: 95774 | C4: 79446 | D4: 109530 | E4: 65417 | F4: 82688
A5: Inventory | B5: 337208 | C5: 371412 | D5: 318864 | E5: 140111 | F5: 185700
A6: Prepaid expenses and other current assets | B6: 42463 | C6: 33321 | D6: 29584 | E6: 17686 | F6: 19644
A7: Total current assets | B7: 914405 | C7: 718920 | D7: 770167 | E7: 476497 | F7: 360547
A8: Property and equipment, net | B8: 130714 | C8: 124587 | D8: 119044 | E8: 78075 | F8: 82610
A9: Operating lease right-of-use assets | B9: 77556 | C9: 55406 | D9: 54971 | E9: 34090 | F9: 37768
A10: Goodwill | B10: 54293 | C10: 54293 | D10: 54293 | E10: 54293 | F10: 54293
A11: Intangible assets, net | B11: 117629 | C11: 99429 | D11: 95314 | E11: 92078 | F11: 90850
A12: Other assets | B12: 2595 | C12: 24130 | D12: 2575 | E12: 972 | F12: 2389
A13: Total assets | B13: 1297192 | C13: 1076765 | D13: 1096364 | E13: 737067 | F13: 629539
A14: Current liabilities
A15: Accounts payable | B15: 190392 | C15: 140818 | D15: 191319 | E15: 123621 | F15: 83823
A16: Accrued expenses and other current liabilities | B16: 130026 | C16: 211399 | D16: 132309 | E16: 89068 | F16: 42088
A17: Taxes payable | B17: 33489 | C17: 15289 | D17: 14514 | E17: 18316 | F17: 3329
A18: Accrued payroll and related costs | B18: 23141 | C18: 4847 | D18: 30844 | E18: 25810 | F18: 18119
A19: Operating lease liabilities | B19: 14726 | C19: 12076 | D19: 10167 | E19: 8247 | F19: 7768
A20: Current maturities of long-term debt | B20: 6579 | C20: 24611 | D20: 24560 | E20: 22697 | F20: 15185
A21: Total current liabilities | B21: 398353 | C21: 409040 | D21: 403713 | E21: 287759 | F21: 170312
A22: Long-term debt, net of current portion | B22: 78645 | C22: 71741 | D22: 95741 | E22: 111017 | F22: 281715
A23: Operating lease liabilities, non-current | B23: 76163 | C23: 55649 | D23: 55940 | E23: 36546 | F23: 42200
A24: Other liabilities | B24: 20421 | C24: 13858 | D24: 23147 | E24: 13327 | F24: 13307
A25: Total liabilities | B25: 573582 | C25: 550288 | D25: 578541 | E25: 448649 | F25: 507534
A26: Commitments and contingencies (Note 11)
A27: Stockholders’ Equity
A28: Common stock, par value $0.01; 600,000,000 shares authorized; 88,592,761 and 86,916,210 shares issued and outstanding at December 30, 2023, respectively, and 88,107,787 and 86,431,236 shares issued and outstanding at December 31, 2022, respectively | B28: 886 | C28: 881 | D28: 877 | E28: 871 | F28: 868
A29: Treasury stock, at cost; 1,676,551 shares | B29: -100025 | C29: -100025 | D29: 0 | E29: 0 | F29: 0
A30: Preferred stock, par value $0.01; 30,000,000 shares authorized; no shares issued or outstanding | B30: 0 | C30: 0 | D30: 337735 | E30: 321678 | F30: 310678
A31: Additional paid-in capital | B31: 386377 | C31: 357490 | D31: 178858 | E31: -33744 | F31: -189545
A32: Retained earnings | B32: 438436 | C32: 268551 | D32: 353 | E32: -387 | F32: 4
A33: Accumulated other comprehensive loss | B33: -2064 | C33: -420 | D33: 517823 | E33: 288418 | F33: 122005
A34: Common Equity | B34: =B28+B31+B32+B33 -> 823635 | C34: =C28+C31+C32+C33 -> 626502 | D34: =D28+D31+D32+D33 -> 697911 | E34: =E28+E31+E32+E33 -> 255158 | F34: =F28+F31+F32+F33 -> -66668
A35: Total stockholders’ equity | B35: 723610 | C35: 526477 | D35: 1096364 | E35: 737067 | F35: 629539
A36: Total liabilities and stockholders’ equity | B36: 1297192 | C36: 1076765

Sheet INCOME STATEMENT
A1: CONSOLIDATED STATEMENTS OF OPERATIONS - USD ($) shares in Thousands, $ in Thousands | B1: 12 Months Ended
B2: Dec. 30, 2023 | C2: Dec. 31, 2022 | D2: Dec. 28, 2021 | E2: Dec. 28, 2020 | F2: Dec. 28, 2019
A3: Income Statement [Abstract]
A4: Net sales | B4: 1658713 | C4: 1595222 | D4: 1410989 | E4: 1091721 | F4: 913734
A5: Cost of goods sold | B5: 715527 | C5: 831821 | D5: 594876 | E5: 462918 | F5: 438420
A6: Gross profit | B6: 943186 | C6: 763401 | D6: 816113 | E6: 628803 | F6: 475314
A7: Selling, general, and administrative expenses | B7: 717728 | C7: 637040 | D7: 541175 | E7: 414570 | F7: 385543
A8: Operating income | B8: 225458 | C8: 126361 | D8: 274938 | E8: 214233 | F8: 89771
A9: Interest expense, net | B9: -942 | C9: -4466 | D9: -3339 | E9: -9155 | F9: -21779
A10: Other income (expense), net | B10: 1430 | C10: -5718 | D10: -3189 | E10: 123 | F10: -734
A11: Income before income taxes | B11: 225946 | C11: 116177 | D11: 268410 | E11: 205201 | F11: 67258
A12: Income tax expense | B12: -56061 | C12: -26484 | D12: -55808 | E12: -49400 | F12: -16824
A13: Net income | B13: 169885 | C13: 89693 | D13: 212602 | E13: 155801 | F13: 50434
A14: Net income per share
A15: Basic (in dollars per share) | B15: 1.96 | C15: 1.04 | D15: 2.43 | E15: 1.79 | F15: 0.59
A16: Diluted (in dollars per share) | B16: 1.94 | C16: 1.03 | D16: 2.4 | E16: 1.77 | F16: 0.58
A17: Weighted-average common shares outstanding
A18: Basic (in shares) | B18: 86717 | C18: 86521 | D18: 87425 | E18: 86978 | F18: 85088
B19: 87403 | C19: 87195 | D19: 88666 | E19: 87847 | F19: 86347

Sheet CASH FLOW
A1: CONSOLIDATED STATEMENTS OF CASH FLOWS - USD ($) $ in Thousands | B1: 12 Months Ended
B2: Dec. 30, 2023 | C2: Dec. 31, 2022 | D2: Jan. 01, 2021 | E2: Dec. 28, 2020 | F2: Dec. 28, 2019
A3: Cash Flows from Operating Activities:
A4: Net income | B4: 169885 | C4: 89693 | D4: 212602 | E4: 155801 | F4: 50434
A5: Adjustments to reconcile net income to cash provided by operating activities:
A6: Depreciation and amortization | B6: 46434 | C6: 39847 | D6: 32070 | E6: 30535 | F6: 28959
A7: Amortization of deferred financing fees | B7: 604 | C7: 601 | D7: 679 | E7: 935 | F7: 2189
A8: Stock-based compensation | B8: 29800 | C8: 17799 | D8: 15474 | E8: 9009 | F8: 52332
A9: Deferred income taxes | B9: 25561 | C9: -403 | D9: 5147 | E9: -3827 | F9: 15615
A10: Impairment of long-lived assets | B10: 2927 | C10: 1229 | D10: 2473 | E10: 1051 | F10: 616
A11: Loss on prepayment, modification, or extinguishment of debt | B11: 330 | C11: 0 | D11: 0 | E11: 1064 | F11: 643
A12: Product recalls | B12: 1895 | C12: 97176 | D12: 0 | E12: -74 | F12: 0
A13: Other | B13: -6163 | C13: 2039 | D13: 1022
A14: Changes in operating assets and liabilities: | E14: 16353 | F14: -19940
A15: Accounts receivable, net | B15: -15683 | C15: 30448 | D15: -44681 | E15: 46052 | F15: -40541
A16: Inventory | B16: 33675 | C16: -91624 | D16: -179803 | E16: 1982 | F16: -6798
A17: Other current assets | B17: -7933 | C17: -2187 | D17: -10587 | E17: 89125 | F17: 6614
A18: Accounts payable and accrued expenses | B18: -15144 | C18: -86242 | D18: 112773 | E18: 14943 | F18: -3101
A19: Taxes payable | B19: 18156 | C19: 439 | D19: -3781 | E19: 3478 | F19: -129
A20: Other | B20: 1598 | C20: 2079 | D20: 3132 | E20: 366427 | F20: 86893
A21: Net cash provided by operating activities | B21: 285942 | C21: 100894 | D21: 146520
A22: Cash Flows from Investing Activities: | E22: -15566 | F22: -32077
A23: Purchases of property and equipment | B23: -50672 | C23: -45929 | D23: -56121 | E23: -7378 | F23: -16614
A24: Additions of intangibles, net | B24: -22152 | C24: -10981 | D24: -9635 | E24: 0 | F24: 0
A25: Net cash used in investing activities | B25: -72824 | C25: -56910 | D25: -65756 | E25: -22944 | F25: -48691
A26: Cash Flows from Financing Activities:
A27: Repayments of long‑term debt | B27: -7734 | C27: -22500 | D27: -22500 | E27: 50000 | F27: 0
A28: Proceeds from employee stock transactions | B28: 1573 | C28: 3821 | D28: 4095 | E28: -50000 | F28: 0
A29: Taxes paid in connection with employee stock transactions | B29: -2481 | C29: -1861 | D29: -3506 | E29: -165000 | F29: -34875
A30: Finance lease principal payment | B30: -2130 | C30: -2063 | D30: -1108 | E30: 3022 | F30: 3561
A31: Repurchase of common stock | B31: 0 | C31: -100025 | D31: 0 | E31: -1028 | F31: -13516
A32: Payments of deferred financing fees | B32: -2824 | C32: 0 | D32: 0 | E32: -185 | F32: -74
A33: Net cash used in financing activities | B33: -13596 | C33: -122628 | D33: -23019 | E33: 0 | F33: -64250
A34: Effect of exchange rate changes on cash | B34: 4697 | C34: 1196 | D34: 1161 | E34: 0 | F34: 66238
A35: Net increase (decrease) in cash | B35: 204219 | C35: -77448 | D35: 58906 | E35: 0 | F35: -2135
A36: Cash, beginning of period | B36: 234741 | C36: 312189 | D36: 253283 | E36: 0 | F36: -636
A37: Cash, end of period | B37: 438960 | C37: 234741 | D37: 312189 | E37: 0 | F37: 0
A38: Supplemental cash flow information:: | E38: 0 | F38: 0
A39: Interest paid | B39: 6688 | C39: 2961 | D39: 2365 | E39: -163191 | F39: -45687
A40: Income taxes paid, net of refunds | B40: 14131 | C40: 58822 | D40: 58819 | E40: 476 | F40: -51
...

Sheet FUTURE PROJECTION
B3: YETI STOCK
F4: Actual
B5: Date | C5: Adj Close | E5: Date | F5: Adj Close | G5: Forecast | H5: Abs Error | I5: Error^2 | J5: %Error | K5: MAD | L5: MSE | M5: MAPE
B6: 45293 | C6: 50.369999 | E6: 45659 | F6: 37.52 | G6: =-0.0079*E6+399.95 -> 39.2439 | H6: =ABS(G6-F6) -> 1.7238995 | I6: =H6^2 -> 2.9718296 | J6: =H6/F6 -> 0.045946149 | K6: =ABS(H6:H8) -> 1.7238995 | L6: =ABS(I6:I8) -> 2.9718296 | M6: =ABS(J6:J8) -> 0.045946149
B7: 45294 | C7: 47.139999 | E7: 45660 | F7: 38.119999 | G7: =-0.0079*E7+399.95 -> 39.236 | H7: =ABS(G7-F7) -> 1.1160011 | I7: =H7^2 -> 1.2454584 | J7: =H7/F7 -> 0.029275999 | K7: R-Squard = | L7: 0.0771
B8: 45295 | C8: 46.080002 | E8: 45663 | F8: 38.130001 | G8: =-0.0079*E8+399.95 -> 39.2123 | H8: =ABS(G8-F8) -> 1.0822989 | I8: =H8^2 -> 1.171371 | J8: =H8/F8 -> 0.028384445 | K8: r = | L8: =SQRT(L7) -> 0.27766887
B9: 45296 | C9: 45.57
B10: 45299 | C10: 46.52
B11: 45300 | C11: 46.610001
B12: 45301 | C12: 47.400002
B13: 45302 | C13: 46.470001
B14: 45303 | C14: 45.75
B15: 45307 | C15: 45.84
B16: 45308 | C16: 44.68
B17: 45309 | C17: 44.900002
B18: 45310 | C18: 45.790001
B19: 45313 | C19: 46.919998
B20: 45314 | C20: 46.439999
... B257: 45657 | C257: 38.509998
